<?xml version="1.0" ?>
<!-- =================================================================================== -->
<!-- |    This document was autogenerated by xacro from src/four_wheel_vehicle/urdf/base.xacro | -->
<!-- |    EDITING THIS FILE BY HAND IS NOT RECOMMENDED                                 | -->
<!-- =================================================================================== -->
<robot>
  <material name="blue">
    <color rgba="0 0 0.5 1"/>
  </material>
  <material name="grey">
    <color rgba="0.5 0.5 0.5 1"/>
  </material>
  <material name="orange">
    <color rgba="1.0 0.5 0 1"/>
  </material>
  <material name="yellow">
    <color rgba="1.0 1.0 0 1"/>
  </material>
  <link name="base_footprint"/>
  <link name="base_link">
    <visual>
      <geometry>
        <box size="0.6 0.4 0.2"/>
      </geometry>
      <origin rpy="0 0 0" xyz="0 0 0.1"/>
      <material name="blue"/>
    </visual>
    <collision>
      <geometry>
        <box size="0.6 0.4 0.2"/>
      </geometry>
      <origin rpy="0 0 0" xyz="0 0 0.1"/>
    </collision>
    <inertial>
      <origin rpy="0 0 0" xyz="0 0 0.1"/>
      <mass value="5.0"/>
      <inertia ixx="0.6666666666666667" ixy="0" ixz="0" iyy="0.6666666666666667" iyz="0" izz="0.6666666666666667"/>
    </inertial>
  </link>
  <link name="front_left_wheel_link">
    <visual>
      <geometry>
        <cylinder length="0.05" radius="0.1"/>
      </geometry>
      <origin rpy="1.5708 0 0" xyz="0 0 0"/>
      <material name="grey"/>
    </visual>
    <collision>
      <geometry>
        <cylinder length="0.05" radius="0.1"/>
      </geometry>
      <origin rpy="1.5708 0 0" xyz="0 0 0"/>
    </collision>
    <inertial>
      <origin rpy="1.5708 0 0" xyz="0 0 0"/>
      <mass value="1.0"/>
      <inertia ixx="0.010833333333333335" ixy="0" ixz="0" iyy="0.010833333333333335" iyz="0" izz="0.010833333333333335"/>
    </inertial>
  </link>
  <link name="front_right_wheel_link">
    <visual>
      <geometry>
        <cylinder length="0.05" radius="0.1"/>
      </geometry>
      <origin rpy="1.5708 0 0" xyz="0 0 0"/>
      <material name="grey"/>
    </visual>
    <collision>
      <geometry>
        <cylinder length="0.05" radius="0.1"/>
      </geometry>
      <origin rpy="1.5708 0 0" xyz="0 0 0"/>
    </collision>
    <inertial>
      <origin rpy="1.5708 0 0" xyz="0 0 0"/>
      <mass value="1.0"/>
      <inertia ixx="0.010833333333333335" ixy="0" ixz="0" iyy="0.010833333333333335" iyz="0" izz="0.010833333333333335"/>
    </inertial>
  </link>
  <link name="rear_left_wheel_link">
    <visual>
      <geometry>
        <cylinder length="0.05" radius="0.1"/>
      </geometry>
      <origin rpy="1.5708 0 0" xyz="0 0 0"/>
      <material name="grey"/>
    </visual>
    <collision>
      <geometry>
        <cylinder length="0.05" radius="0.1"/>
      </geometry>
      <origin rpy="1.5708 0 0" xyz="0 0 0"/>
    </collision>
    <inertial>
      <origin rpy="1.5708 0 0" xyz="0 0 0"/>
      <mass value="1.0"/>
      <inertia ixx="0.010833333333333335" ixy="0" ixz="0" iyy="0.010833333333333335" iyz="0" izz="0.010833333333333335"/>
    </inertial>
  </link>
  <link name="rear_right_wheel_link">
    <visual>
      <geometry>
        <cylinder length="0.05" radius="0.1"/>
      </geometry>
      <origin rpy="1.5708 0 0" xyz="0 0 0"/>
      <material name="grey"/>
    </visual>
    <collision>
      <geometry>
        <cylinder length="0.05" radius="0.1"/>
      </geometry>
      <origin rpy="1.5708 0 0" xyz="0 0 0"/>
    </collision>
    <inertial>
      <origin rpy="1.5708 0 0" xyz="0 0 0"/>
      <mass value="1.0"/>
      <inertia ixx="0.010833333333333335" ixy="0" ixz="0" iyy="0.010833333333333335" iyz="0" izz="0.010833333333333335"/>
    </inertial>
  </link>
  <joint name="base_joint" type="fixed">
    <parent link="base_footprint"/>
    <child link="base_link"/>
    <origin rpy="0 0 0" xyz="0 0 0.1"/>
  </joint>
  <joint name="front_left_wheel_joint" type="revolute">
    <parent link="base_link"/>
    <child link="front_left_wheel_link"/>
    <origin rpy="0 0 0" xyz="0.24 0.225 0"/>
    <axis xyz="0 1 0"/>
    <limit effort="100" lower="0" upper="3.14" velocity="10"/>
  </joint>
  <joint name="front_right_wheel_joint" type="revolute">
    <parent link="base_link"/>
    <child link="front_right_wheel_link"/>
    <origin rpy="0 0 0" xyz="0.24 -0.225 0"/>
    <axis xyz="0 1 0"/>
    <limit effort="100" lower="0" upper="3.14" velocity="10"/>
  </joint>
  <joint name="rear_left_wheel_joint" type="revolute">
    <parent link="base_link"/>
    <child link="rear_left_wheel_link"/>
    <origin rpy="0 0 0" xyz="-0.24 0.225 0"/>
    <axis xyz="0 1 0"/>
    <limit effort="100" lower="0" upper="3.14" velocity="10"/>
  </joint>
  <joint name="rear_right_wheel_joint" type="revolute">
    <parent link="base_link"/>
    <child link="rear_right_wheel_link"/>
    <origin rpy="0 0 0" xyz="-0.24 -0.225 0"/>
    <axis xyz="0 1 0"/>
    <limit effort="100" lower="0" upper="3.14" velocity="10"/>
  </joint>
</robot>
